I'm sorry, but an uncaught exception occurred.

While running game code:
  File "renpy/common/00start.rpy", line 275, in script
    python:
  File "renpy/common/00start.rpy", line 279, in <module>
    renpy.call_in_new_context("_main_menu")
  File "game/quiz.rpy", line 573, in script
    call screen status with fade
ScriptError: could not find label 'quiz_init'.

-- Full Traceback ------------------------------------------------------------

Full traceback:
  File "renpy/common/00start.rpy", line 275, in script
    python:
  File "D:\renpy-8.1.3-sdk\renpy\ast.py", line 1138, in execute
    renpy.python.py_exec_bytecode(self.code.bytecode, self.hide, store=self.store)
  File "D:\renpy-8.1.3-sdk\renpy\python.py", line 1122, in py_exec_bytecode
    exec(bytecode, globals, locals)
  File "renpy/common/00start.rpy", line 279, in <module>
    renpy.call_in_new_context("_main_menu")
  File "D:\renpy-8.1.3-sdk\renpy\game.py", line 349, in call_in_new_context
    return renpy.execution.run_context(False)
  File "D:\renpy-8.1.3-sdk\renpy\execution.py", line 955, in run_context
    context.run()
  File "game/quiz.rpy", line 573, in script
    call screen status with fade
  File "D:\renpy-8.1.3-sdk\renpy\script.py", line 1013, in lookup
    raise ScriptError("could not find label '%s'." % str(original))
ScriptError: could not find label 'quiz_init'.

Windows-10-10.0.22621 AMD64
Ren'Py 8.1.3.23091805
Kodigo 1.0
Sat Mar 23 01:26:25 2024
